Workbook

Sheet Activity
A1: A. | B1: Arrival every 2 minutes, Service time = 3 mins
A2: Customer No. | B2: Arrival Time | C2: Interarrival Time (with respect to the previous arrival time) | D2: Service Time (requested by Customer) | E2: Service Start Time | F2: Service End Time | G2: Waiting Time | H2: Queue Length at Arrival | I2: Idle Time of Server
A3: 1 | B3: 0 | C3: 0 | D3: 3 | E3: 0 | F3: =D3+E3 -> 3 | G3: 0 | H3: 0 | I3: 0 | K3: Total waiting time | L3: =SUM(G3:G17) -> 105
A4: 2 | B4: 2 | C4: =C3+B4 -> 2 | D4: 3 | E4: =F3 -> 3 | F4: =D4+E4 -> 6 | G4: =F3-C4 -> 1 | H4: =COUNTIF($F$3:F3, ">" & C4) -> 1 | I4: =ABS(E4-F3) -> 0 | K4: Average waiting time | L4: =AVERAGE(G3:G17) -> 7
A5: 3 | B5: 2 | C5: =C4+B5 -> 4 | D5: 3 | E5: =F4 -> 6 | F5: =D5+E5 -> 9 | G5: =F4-C5 -> 2 | H5: =COUNTIF($F$3:F4, ">" & C5) -> 1 | I5: =ABS(E5-F4) -> 0 | K5: Max queue length | L5: =MAX(H4:H18) -> 5
A6: 4 | B6: 2 | C6: =C5+B6 -> 6 | D6: 3 | E6: =F5 -> 9 | F6: =D6+E6 -> 12 | G6: =F5-C6 -> 3 | H6: =COUNTIF($F$3:F5, ">" & C6) -> 1 | I6: =ABS(E6-F5) -> 0
A7: 5 | B7: 2 | C7: =C6+B7 -> 8 | D7: 3 | E7: =F6 -> 12 | F7: =D7+E7 -> 15 | G7: =F6-C7 -> 4 | H7: =COUNTIF($F$3:F6, ">" & C7) -> 2 | I7: =ABS(E7-F6) -> 0 | K7: Server utilization
A8: 6 | B8: 2 | C8: =C7+B8 -> 10 | D8: 3 | E8: =F7 -> 15 | F8: =D8+E8 -> 18 | G8: =F7-C8 -> 5 | H8: =COUNTIF($F$3:F7, ">" & C8) -> 2 | I8: =ABS(E8-F7) -> 0 | K8: Total busy time: | L8: =SUM(D3:D17) -> 45
A9: 7 | B9: 2 | C9: =C8+B9 -> 12 | D9: 3 | E9: =F8 -> 18 | F9: =D9+E9 -> 21 | G9: =F8-C9 -> 6 | H9: =COUNTIF($F$3:F8, ">" & C9) -> 2 | I9: =ABS(E9-F8) -> 0 | K9: Total server time: | L9: =SUM(D3:D17) -> 45
A10: 8 | B10: 2 | C10: =C9+B10 -> 14 | D10: 3 | E10: =F9 -> 21 | F10: =D10+E10 -> 24 | G10: =F9-C10 -> 7 | H10: =COUNTIF($F$3:F9, ">" & C10) -> 3 | I10: =ABS(E10-F9) -> 0
A11: 9 | B11: 2 | C11: =C10+B11 -> 16 | D11: 3 | E11: =F10 -> 24 | F11: =D11+E11 -> 27 | G11: =F10-C11 -> 8 | H11: =COUNTIF($F$3:F10, ">" & C11) -> 3 | I11: =ABS(E11-F10) -> 0
A12: 10 | B12: 2 | C12: =C11+B12 -> 18 | D12: 3 | E12: =F11 -> 27 | F12: =D12+E12 -> 30 | G12: =F11-C12 -> 9 | H12: =COUNTIF($F$3:F11, ">" & C12) -> 3 | I12: =ABS(E12-F11) -> 0
A13: 11 | B13: 2 | C13: =C12+B13 -> 20 | D13: 3 | E13: =F12 -> 30 | F13: =D13+E13 -> 33 | G13: =F12-C13 -> 10 | H13: =COUNTIF($F$3:F12, ">" & C13) -> 4 | I13: =ABS(E13-F12) -> 0
A14: 12 | B14: 2 | C14: =C13+B14 -> 22 | D14: 3 | E14: =F13 -> 33 | F14: =D14+E14 -> 36 | G14: =F13-C14 -> 11 | H14: =COUNTIF($F$3:F13, ">" & C14) -> 4 | I14: =ABS(E14-F13) -> 0
A15: 13 | B15: 2 | C15: =C14+B15 -> 24 | D15: 3 | E15: =F14 -> 36 | F15: =D15+E15 -> 39 | G15: =F14-C15 -> 12 | H15: =COUNTIF($F$3:F14, ">" & C15) -> 4 | I15: =ABS(E15-F14) -> 0
A16: 14 | B16: 2 | C16: =C15+B16 -> 26 | D16: 3 | E16: =F15 -> 39 | F16: =D16+E16 -> 42 | G16: =F15-C16 -> 13 | H16: =COUNTIF($F$3:F15, ">" & C16) -> 5 | I16: =ABS(E16-F15) -> 0
A17: 15 | B17: 2 | C17: =C16+B17 -> 28 | D17: 3 | E17: =F16 -> 42 | F17: =D17+E17 -> 45 | G17: =F16-C17 -> 14 | H17: =COUNTIF($F$3:F16, ">" & C17) -> 5 | I17: =ABS(E17-F16) -> 0
A19: B. | B19: Arrival every 2 minutes, Service time = 2 mins
A20: Customer No. | B20: Arrival Time | C20: Interarrival Time (with respect to the previous arrival time) | D20: Service Time (requested by Customer) | E20: Service Start Time | F20: Service End Time | G20: Waiting Time | H20: Queue Length at Arrival | I20: Idle Time of Server
A21: 1 | B21: 0 | C21: 0 | D21: 2 | E21: 0 | F21: =D21+E21 -> 2 | G21: 0 | H21: 0 | I21: 0 | K21: Total waiting time | L21: =AVERAGE(G21:G35) -> 0
A22: 2 | B22: 2 | C22: =SUM(C21+B22) -> 2 | D22: 2 | E22: =F21 -> 2 | F22: =D22+E22 -> 4 | G22: =F21-C22 -> 0 | H22: =COUNTIF($F$21:F21, ">" & C22) -> 0 | I22: =ABS(E22-F21) -> 0 | K22: Average waiting time | L22: =AVERAGE(G21:G35) -> 0
A23: 3 | B23: 2 | C23: =SUM(C22+B23) -> 4 | D23: 2 | E23: =F22 -> 4 | F23: =D23+E23 -> 6 | G23: =F22-C23 -> 0 | H23: =COUNTIF($F$21:F22, ">" & C23) -> 0 | I23: =ABS(E23-F22) -> 0 | K23: Max queue length | L23: =MAX(H21:H35) -> 0
A24: 4 | B24: 2 | C24: =SUM(C23+B24) -> 6 | D24: 2 | E24: =F23 -> 6 | F24: =D24+E24 -> 8 | G24: =F23-C24 -> 0 | H24: =COUNTIF($F$21:F23, ">" & C24) -> 0 | I24: =ABS(E24-F23) -> 0
A25: 5 | B25: 2 | C25: =SUM(C24+B25) -> 8 | D25: 2 | E25: =F24 -> 8 | F25: =D25+E25 -> 10 | G25: =F24-C25 -> 0 | H25: =COUNTIF($F$21:F24, ">" & C25) -> 0 | I25: =ABS(E25-F24) -> 0 | K25: Server utilization
A26: 6 | B26: 2 | C26: =SUM(C25+B26) -> 10 | D26: 2 | E26: =F25 -> 10 | F26: =D26+E26 -> 12 | G26: =F25-C26 -> 0 | H26: =COUNTIF($F$21:F25, ">" & C26) -> 0 | I26: =ABS(E26-F25) -> 0 | K26: Total busy time: | L26: =SUM(D21:D35) -> 30
A27: 7 | B27: 2 | C27: =SUM(C26+B27) -> 12 | D27: 2 | E27: =F26 -> 12 | F27: =D27+E27 -> 14 | G27: =F26-C27 -> 0 | H27: =COUNTIF($F$21:F26, ">" & C27) -> 0 | I27: =ABS(E27-F26) -> 0 | K27: Total server time: | L27: =SUM(D21:D35) -> 30
A28: 8 | B28: 2 | C28: =SUM(C27+B28) -> 14 | D28: 2 | E28: =F27 -> 14 | F28: =D28+E28 -> 16 | G28: =F27-C28 -> 0 | H28: =COUNTIF($F$21:F27, ">" & C28) -> 0 | I28: =ABS(E28-F27) -> 0
A29: 9 | B29: 2 | C29: =SUM(C28+B29) -> 16 | D29: 2 | E29: =F28 -> 16 | F29: =D29+E29 -> 18 | G29: =F28-C29 -> 0 | H29: =COUNTIF($F$21:F28, ">" & C29) -> 0 | I29: =ABS(E29-F28) -> 0
A30: 10 | B30: 2 | C30: =SUM(C29+B30) -> 18 | D30: 2 | E30: =F29 -> 18 | F30: =D30+E30 -> 20 | G30: =F29-C30 -> 0 | H30: =COUNTIF($F$21:F29, ">" & C30) -> 0 | I30: =ABS(E30-F29) -> 0
A31: 11 | B31: 2 | C31: =SUM(C30+B31) -> 20 | D31: 2 | E31: =F30 -> 20 | F31: =D31+E31 -> 22 | G31: =F30-C31 -> 0 | H31: =COUNTIF($F$21:F30, ">" & C31) -> 0 | I31: =ABS(E31-F30) -> 0
A32: 12 | B32: 2 | C32: =SUM(C31+B32) -> 22 | D32: 2 | E32: =F31 -> 22 | F32: =D32+E32 -> 24 | G32: =F31-C32 -> 0 | H32: =COUNTIF($F$21:F31, ">" & C32) -> 0 | I32: =ABS(E32-F31) -> 0
A33: 13 | B33: 2 | C33: =SUM(C32+B33) -> 24 | D33: 2 | E33: =F32 -> 24 | F33: =D33+E33 -> 26 | G33: =F32-C33 -> 0 | H33: =COUNTIF($F$21:F32, ">" & C33) -> 0 | I33: =ABS(E33-F32) -> 0
A34: 14 | B34: 2 | C34: =SUM(C33+B34) -> 26 | D34: 2 | E34: =F33 -> 26 | F34: =D34+E34 -> 28 | G34: =F33-C34 -> 0 | H34: =COUNTIF($F$21:F33, ">" & C34) -> 0 | I34: =ABS(E34-F33) -> 0
A35: 15 | B35: 2 | C35: =SUM(C34+B35) -> 28 | D35: 2 | E35: =F34 -> 28 | F35: =D35+E35 -> 30 | G35: =F34-C35 -> 0 | H35: =COUNTIF($F$21:F34, ">" & C35) -> 0 | I35: =ABS(E35-F34) -> 0
A37: C. | B37: Arrival every 1 minute, Service time = 2 mins
A38: Customer No. | B38: Arrival Time | C38: Interarrival Time (with respect to the previous arrival time) | D38: Service Time (requested by Customer) | E38: Service Start Time | F38: Service End Time | G38: Waiting Time | H38: Queue Length at Arrival | I38: Idle Time of Server
A39: 1 | B39: 0 | C39: 0 | D39: 2 | E39: 0 | F39: =D39+E39 -> 2 | G39: 0 | H39: 0 | I39: 0 | K39: Total waiting time | L39: =AVERAGE(G39:G53) -> 7
A40: 2 | B40: 1 | C40: =C39+B40 -> 1 | D40: 2 | E40: =F39 -> 2 | F40: =D40+E40 -> 4 | G40: =F39-C40 -> 1 | H40: =COUNTIF($F$39:F39, ">" & C40) -> 1 | I40: =ABS(E40-F39) -> 0 | K40: Average waiting time | L40: =AVERAGE(G40:G54) -> 7.5
A41: 3 | B41: 1 | C41: =C40+B41 -> 2 | D41: 2 | E41: =F40 -> 4 | F41: =D41+E41 -> 6 | G41: =F40-C41 -> 2 | H41: =COUNTIF($F$39:F40, ">" & C41) -> 1 | I41: =ABS(E41-F40) -> 0 | K41: Max queue length | L41: =MAX(H40:H54) -> 7
A42: 4 | B42: 1 | C42: =C41+B42 -> 3 | D42: 2 | E42: =F41 -> 6 | F42: =D42+E42 -> 8 | G42: =F41-C42 -> 3 | H42: =COUNTIF($F$39:F41, ">" & C42) -> 2 | I42: =ABS(E42-F41) -> 0 | K42: Server utilization
...

Sheet Report and Reflection
R1: A | S1: B | T1: C | U1: D
Q2: Total waiting time | R2: 105 | S2: 0 | T2: 7 | U2: =Activity!L57 -> 164
Q3: Average waiting time | R3: 7 | S3: 0 | T3: 7.5 | U3: =Activity!L58 -> 10.933333
Q4: Max queue length | R4: 5 | S4: 0 | T4: 7 | U4: =Activity!L59 -> 7
Q6: Server utilization
Q7: Total busy time | R7: 45 | S7: 30 | T7: 30 | U7: =Activity!L62 -> 48
Q8: Total server time | R8: 45 | S8: 30 | T8: 30 | U8: =Activity!L63 -> 48
